<?xml version="1.0" encoding="utf-8"?>
<!-- This URDF was automatically created by SolidWorks to URDF Exporter! Originally created by Stephen Brawner (brawner@gmail.com) 
     Commit Version: 1.6.0-4-g7f85cfe  Build Version: 1.6.7995.38578
     For more information, please see http://wiki.ros.org/sw_urdf_exporter -->
<robot
  name="robot_agv">
  <link
    name="base_link">
    <inertial>
      <origin
        xyz="-4.50968266915222E-05 -4.35308039614668E-13 -0.0197136601969749"
        rpy="0 0 0" />
      <mass
        value="0.489034358952568" />
      <inertia
        ixx="0.000921386087712042"
        ixy="1.54892273351734E-12"
        ixz="8.99166324549194E-08"
        iyy="0.000914602218706382"
        iyz="7.7311999509303E-09"
        izz="0.00169182386938637" />
    </inertial>
    <visual>
      <origin
        xyz="0 0 0"
        rpy="0 0 0" />
      <geometry>
        <mesh
          filename="package://robot_agv/meshes/base_link.STL" />
      </geometry>
      <material
        name="">
        <color
          rgba="0.792156862745098 0.819607843137255 0.933333333333333 1" />
      </material>
    </visual>
    <collision>
      <origin
        xyz="0 0 0"
        rpy="0 0 0" />
      <geometry>
        <mesh
          filename="package://robot_agv/meshes/base_link.STL" />
      </geometry>
    </collision>
  </link>
  <link
    name="link_TP">
    <inertial>
      <origin
        xyz="3.88578058618805E-16 1.87350135405495E-16 -0.00750000000000017"
        rpy="0 0 0" />
      <mass
        value="0.0950017618445553" />
      <inertia
        ixx="5.00896789325418E-05"
        ixy="3.89570784494416E-37"
        ixz="-4.23516473627149E-22"
        iyy="5.00896789325418E-05"
        iyz="-1.18381694266161E-37"
        izz="9.66167917959127E-05" />
    </inertial>
    <visual>
      <origin
        xyz="0 0 0"
        rpy="0 0 0" />
      <geometry>
        <mesh
          filename="package://robot_agv/meshes/link_TP.STL" />
      </geometry>
      <material
        name="">
        <color
          rgba="0.792156862745098 0.819607843137255 0.933333333333333 1" />
      </material>
    </visual>
    <collision>
      <origin
        xyz="0 0 0"
        rpy="0 0 0" />
      <geometry>
        <mesh
          filename="package://robot_agv/meshes/link_TP.STL" />
      </geometry>
    </collision>
  </link>
  <joint
    name="joint_TP"
    type="continuous">
    <origin
      xyz="0.0711464466081992 -0.100000000000508 -0.0230000000015247"
      rpy="-1.57079632681698 0 0" />
    <parent
      link="base_link" />
    <child
      link="link_TP" />
    <axis
      xyz="0 0 1" />
    <dynamics
      damping="0.1"
      friction="0.1" />
  </joint>
  <link
    name="link_TT">
    <inertial>
      <origin
        xyz="5.82867087928207E-16 1.94289029309402E-16 0.00749999999999981"
        rpy="0 0 0" />
      <mass
        value="0.0950017618445552" />
      <inertia
        ixx="5.00896789325417E-05"
        ixy="-3.8959993982459E-37"
        ixz="-1.33359302107442E-36"
        iyy="5.00896789325417E-05"
        iyz="-7.14594954479365E-38"
        izz="9.66167917959126E-05" />
    </inertial>
    <visual>
      <origin
        xyz="0 0 0"
        rpy="0 0 0" />
      <geometry>
        <mesh
          filename="package://robot_agv/meshes/link_TT.STL" />
      </geometry>
      <material
        name="">
        <color
          rgba="0.792156862745098 0.819607843137255 0.933333333333333 1" />
      </material>
    </visual>
    <collision>
      <origin
        xyz="0 0 0"
        rpy="0 0 0" />
      <geometry>
        <mesh
          filename="package://robot_agv/meshes/link_TT.STL" />
      </geometry>
    </collision>
  </link>
  <joint
    name="joint_TT"
    type="continuous">
    <origin
      xyz="0.071146446608199 0.0999999999994926 -0.023000000005942"
      rpy="-1.57079632681698 0 0" />
    <parent
      link="base_link" />
    <child
      link="link_TT" />
    <axis
      xyz="0 0 1" />
    <dynamics
      damping="0.1"
      friction="0.1" />
  </joint>
  <link
    name="link_ST">
    <inertial>
      <origin
        xyz="8.60422844084496E-16 -4.37150315946155E-16 0.00750000000000003"
        rpy="0 0 0" />
      <mass
        value="0.0950017618445552" />
      <inertia
        ixx="5.00896789325417E-05"
        ixy="0"
        ixz="1.64808506129101E-19"
        iyy="5.00896789325417E-05"
        iyz="-6.27560060914619E-20"
        izz="9.66167917959126E-05" />
    </inertial>
    <visual>
      <origin
        xyz="0 0 0"
        rpy="0 0 0" />
      <geometry>
        <mesh
          filename="package://robot_agv/meshes/link_ST.STL" />
      </geometry>
      <material
        name="">
        <color
          rgba="0.792156862745098 0.819607843137255 0.933333333333333 1" />
      </material>
    </visual>
    <collision>
      <origin
        xyz="0 0 0"
        rpy="0 0 0" />
      <geometry>
        <mesh
          filename="package://robot_agv/meshes/link_ST.STL" />
      </geometry>
    </collision>
  </link>
  <joint
    name="joint_ST"
    type="continuous">
    <origin
      xyz="-0.0851464466106142 0.0999999999994928 -0.0229999999977417"
      rpy="-1.57079632681907 0.418974378731321 0" />
    <parent
      link="base_link" />
    <child
      link="link_ST" />
    <axis
      xyz="0 0 1" />
    <dynamics
      damping="0.1"
      friction="0.1" />
  </joint>
  <link
    name="link_SP">
    <inertial>
      <origin
        xyz="-1.38777878078145E-17 0 -0.00750000000000034"
        rpy="0 0 0" />
      <mass
        value="0.0950017618445553" />
      <inertia
        ixx="5.00896789325418E-05"
        ixy="4.2351647362715E-22"
        ixz="1.65371556088239E-19"
        iyy="5.00896789325418E-05"
        iyz="8.93750773687191E-21"
        izz="9.66167917959127E-05" />
    </inertial>
    <visual>
      <origin
        xyz="0 0 0"
        rpy="0 0 0" />
      <geometry>
        <mesh
          filename="package://robot_agv/meshes/link_SP.STL" />
      </geometry>
      <material
        name="">
        <color
          rgba="0.792156862745098 0.819607843137255 0.933333333333333 1" />
      </material>
    </visual>
    <collision>
      <origin
        xyz="0 0 0"
        rpy="0 0 0" />
      <geometry>
        <mesh
          filename="package://robot_agv/meshes/link_SP.STL" />
      </geometry>
    </collision>
  </link>
  <joint
    name="joint_SP"
    type="continuous">
    <origin
      xyz="-0.085146446610614 -0.100000000000507 -0.0229999999933239"
      rpy="-1.57079632681722 -0.146106215270251 0" />
    <parent
      link="base_link" />
    <child
      link="link_SP" />
    <axis
      xyz="0 0 1" />
    <dynamics
      damping="0.1"
      friction="0.1" />
  </joint>
  <link
    name="link_lidar">
    <inertial>
      <origin
        xyz="0.0107513089133826 -1.34961486430996E-14 0.01070114222303"
        rpy="0 0 0" />
      <mass
        value="0.146695752132548" />
      <inertia
        ixx="6.22721120798138E-05"
        ixy="-6.43517984395555E-18"
        ixz="-1.8865807633984E-05"
        iyy="0.00010967399759166"
        iyz="-2.12237100743264E-16"
        izz="0.000125682524276445" />
    </inertial>
    <visual>
      <origin
        xyz="0 0 0"
        rpy="0 0 0" />
      <geometry>
        <mesh
          filename="package://robot_agv/meshes/link_lidar.STL" />
      </geometry>
      <material
        name="">
        <color
          rgba="0.792156862745098 0.819607843137255 0.933333333333333 1" />
      </material>
    </visual>
    <collision>
      <origin
        xyz="0 0 0"
        rpy="0 0 0" />
      <geometry>
        <mesh
          filename="package://robot_agv/meshes/link_lidar.STL" />
      </geometry>
    </collision>
  </link>
  <joint
    name="joint_lidar"
    type="fixed">
    <origin
      xyz="0.0211221138956228 0.00200000000064026 0.0289999999988475"
      rpy="0 0 0" />
    <parent
      link="base_link" />
    <child
      link="link_lidar" />
    <axis
      xyz="0 0 0" />
    <limit
      lower="0"
      upper="0"
      effort="0"
      velocity="0" />
  </joint>
  <link
    name="link_camera">
    <inertial>
      <origin
        xyz="0.00458648494818011 2.01626661366257E-05 3.80160095715988E-05"
        rpy="0 0 0" />
      <mass
        value="0.00436250529984364" />
      <inertia
        ixx="1.77782664708891E-07"
        ixy="5.91438042649722E-12"
        ixz="1.30757112180239E-11"
        iyy="2.52020148511155E-07"
        iyz="1.17624939619964E-09"
        izz="2.52619960333893E-07" />
    </inertial>
    <visual>
      <origin
        xyz="0 0 0"
        rpy="0 0 0" />
      <geometry>
        <mesh
          filename="package://robot_agv/meshes/link_camera.STL" />
      </geometry>
      <material
        name="">
        <color
          rgba="0.627450980392157 0.627450980392157 0.627450980392157 1" />
      </material>
    </visual>
    <collision>
      <origin
        xyz="0 0 0"
        rpy="0 0 0" />
      <geometry>
        <mesh
          filename="package://robot_agv/meshes/link_camera.STL" />
      </geometry>
    </collision>
  </link>
  <joint
    name="joint_camera"
    type="fixed">
    <origin
      xyz="0.111799999998736 0.00120165214283002 -0.0240925411033633"
      rpy="-1.57079632681698 0 0" />
    <parent
      link="base_link" />
    <child
      link="link_camera" />
    <axis
      xyz="0 0 0" />
  </joint>
</robot>