<?xml version="1.0" encoding="utf-8"?>
<!-- This URDF was automatically created by SolidWorks to URDF Exporter! Originally created by Stephen Brawner (brawner@gmail.com) 
     Commit Version: 1.6.0-4-g7f85cfe  Build Version: 1.6.7995.38578
     For more information, please see http://wiki.ros.org/sw_urdf_exporter -->
<robot
  name="robot_agv">
  <link
    name="base_link">
    <inertial>
      <origin
        xyz="-0.0211672107197584 -0.0262524874271211 0.0255000000000222"
        rpy="0 0 0" />
      <mass
        value="0.489034358952568" />
      <inertia
        ixx="0.000921386087712032"
        ixy="-8.99165920315162E-08"
        ixz="1.54892035281115E-12"
        iyy="0.00169182386938638"
        iyz="-7.7311827849915E-09"
        izz="0.000914602218706382" />
    </inertial>
    <visual>
      <origin
        xyz="0 0 0"
        rpy="0 0 0" />
      <geometry>
        <mesh
          filename="package://robot_agv/meshes/base_link.STL" />
      </geometry>
      <material
        name="">
        <color
          rgba="0.792156862745098 0.819607843137255 0.933333333333333 1" />
      </material>
    </visual>
    <collision>
      <origin
        xyz="0 0 0"
        rpy="0 0 0" />
      <geometry>
        <mesh
          filename="package://robot_agv/meshes/base_link.STL" />
      </geometry>
    </collision>
  </link>
  <link
    name="link_TP">
    <inertial>
      <origin
        xyz="3.81639164714898E-16 1.87350135405495E-16 -0.00750000000000017"
        rpy="0 0 0" />
      <mass
        value="0.0950017618445553" />
      <inertia
        ixx="5.00896789325418E-05"
        ixy="3.89570784494416E-37"
        ixz="-4.23516473627149E-22"
        iyy="5.00896789325418E-05"
        iyz="-1.18381694266161E-37"
        izz="9.66167917959127E-05" />
    </inertial>
    <visual>
      <origin
        xyz="0 0 0"
        rpy="0 0 0" />
      <geometry>
        <mesh
          filename="package://robot_agv/meshes/link_TP.STL" />
      </geometry>
      <material
        name="">
        <color
          rgba="0.792156862745098 0.819607843137255 0.933333333333333 1" />
      </material>
    </visual>
    <collision>
      <origin
        xyz="0 0 0"
        rpy="0 0 0" />
      <geometry>
        <mesh
          filename="package://robot_agv/meshes/link_TP.STL" />
      </geometry>
    </collision>
  </link>
  <joint
    name="joint_TP"
    type="continuous">
    <origin
      xyz="0.0500243327153047 -0.0229661476240979 -0.0744999999999778"
      rpy="0 0 0" />
    <parent
      link="base_link" />
    <child
      link="link_TP" />
    <axis
      xyz="0 0 1" />
    <dynamics
      damping="0.1"
      friction="0.1" />
  </joint>
  <link
    name="link_TT">
    <inertial>
      <origin
        xyz="5.82867087928207E-16 1.97758476261356E-16 0.00749999999999981"
        rpy="0 0 0" />
      <mass
        value="0.0950017618445552" />
      <inertia
        ixx="5.00896789325417E-05"
        ixy="3.89570784494416E-37"
        ixz="-1.33359302107442E-36"
        iyy="5.00896789325417E-05"
        iyz="-1.12211496868046E-37"
        izz="9.66167917959126E-05" />
    </inertial>
    <visual>
      <origin
        xyz="0 0 0"
        rpy="0 0 0" />
      <geometry>
        <mesh
          filename="package://robot_agv/meshes/link_TT.STL" />
      </geometry>
      <material
        name="">
        <color
          rgba="0.792156862745098 0.819607843137255 0.933333333333333 1" />
      </material>
    </visual>
    <collision>
      <origin
        xyz="0 0 0"
        rpy="0 0 0" />
      <geometry>
        <mesh
          filename="package://robot_agv/meshes/link_TT.STL" />
      </geometry>
    </collision>
  </link>
  <joint
    name="joint_TT"
    type="continuous">
    <origin
      xyz="0.0500243327153045 -0.0229661476240979 0.125500000000023"
      rpy="0 0 0" />
    <parent
      link="base_link" />
    <child
      link="link_TT" />
    <axis
      xyz="0 0 1" />
    <dynamics
      damping="0.1"
      friction="0.1" />
  </joint>
  <link
    name="link_ST">
    <inertial>
      <origin
        xyz="8.60422844084496E-16 -4.37150315946155E-16 0.00750000000000003"
        rpy="0 0 0" />
      <mass
        value="0.0950017618445552" />
      <inertia
        ixx="5.00896789325417E-05"
        ixy="3.3881317890172E-21"
        ixz="1.64808506129101E-19"
        iyy="5.00896789325417E-05"
        iyz="-6.27560060914619E-20"
        izz="9.66167917959126E-05" />
    </inertial>
    <visual>
      <origin
        xyz="0 0 0"
        rpy="0 0 0" />
      <geometry>
        <mesh
          filename="package://robot_agv/meshes/link_ST.STL" />
      </geometry>
      <material
        name="">
        <color
          rgba="0.792156862745098 0.819607843137255 0.933333333333333 1" />
      </material>
    </visual>
    <collision>
      <origin
        xyz="0 0 0"
        rpy="0 0 0" />
      <geometry>
        <mesh
          filename="package://robot_agv/meshes/link_ST.STL" />
      </geometry>
    </collision>
  </link>
  <joint
    name="joint_ST"
    type="continuous">
    <origin
      xyz="-0.106268560503509 -0.0229661476240978 0.125500000000023"
      rpy="0 0 0.418974378678853" />
    <parent
      link="base_link" />
    <child
      link="link_ST" />
    <axis
      xyz="0 0 1" />
    <dynamics
      damping="0.1"
      friction="0.1" />
  </joint>
  <link
    name="link_SP">
    <inertial>
      <origin
        xyz="-1.38777878078145E-17 0 -0.00750000000000034"
        rpy="0 0 0" />
      <mass
        value="0.0950017618445553" />
      <inertia
        ixx="5.00896789325418E-05"
        ixy="4.2351647362715E-22"
        ixz="1.65371556088239E-19"
        iyy="5.00896789325418E-05"
        iyz="8.93750773687192E-21"
        izz="9.66167917959127E-05" />
    </inertial>
    <visual>
      <origin
        xyz="0 0 0"
        rpy="0 0 0" />
      <geometry>
        <mesh
          filename="package://robot_agv/meshes/link_SP.STL" />
      </geometry>
      <material
        name="">
        <color
          rgba="0.792156862745098 0.819607843137255 0.933333333333333 1" />
      </material>
    </visual>
    <collision>
      <origin
        xyz="0 0 0"
        rpy="0 0 0" />
      <geometry>
        <mesh
          filename="package://robot_agv/meshes/link_SP.STL" />
      </geometry>
    </collision>
  </link>
  <joint
    name="joint_SP"
    type="continuous">
    <origin
      xyz="-0.106268560503509 -0.0229661476240984 -0.0744999999999773"
      rpy="0 0 -0.146106215322719" />
    <parent
      link="base_link" />
    <child
      link="link_SP" />
    <axis
      xyz="0 0 1" />
    <dynamics
      damping="0.1"
      friction="0.1" />
  </joint>
  <link
    name="link_lidar">
    <inertial>
      <origin
        xyz="0.0107513089133826 -1.34996180900515E-14 0.01070114222303"
        rpy="0 0 0" />
      <mass
        value="0.146695752132548" />
      <inertia
        ixx="6.22721120798138E-05"
        ixy="-6.43410614083283E-18"
        ixz="-1.8865807633984E-05"
        iyy="0.00010967399759166"
        iyz="-2.12235089960539E-16"
        izz="0.000125682524276445" />
    </inertial>
    <visual>
      <origin
        xyz="0 0 0"
        rpy="0 0 0" />
      <geometry>
        <mesh
          filename="package://robot_agv/meshes/link_lidar.STL" />
      </geometry>
      <material
        name="">
        <color
          rgba="0.792156862745098 0.819607843137255 0.933333333333333 1" />
      </material>
    </visual>
    <collision>
      <origin
        xyz="0 0 0"
        rpy="0 0 0" />
      <geometry>
        <mesh
          filename="package://robot_agv/meshes/link_lidar.STL" />
      </geometry>
    </collision>
  </link>
  <joint
    name="joint_lidar"
    type="fixed">
    <origin
      xyz="0 -0.0749661476240983 0.0275000000000219"
      rpy="1.5707963267949 0 0" />
    <parent
      link="base_link" />
    <child
      link="link_lidar" />
    <axis
      xyz="0 0 0" />
    <limit
      lower="0"
      upper="0"
      effort="0"
      velocity="0" />
  </joint>
  <link
    name="link_camera">
    <inertial>
      <origin
        xyz="2.01626661366257E-05 -0.00458648494818009 3.80160095716023E-05"
        rpy="0 0 0" />
      <mass
        value="0.00436250529984365" />
      <inertia
        ixx="2.52020148511155E-07"
        ixy="-5.9143804264964E-12"
        ixz="1.17624939619963E-09"
        iyy="1.77782664708891E-07"
        iyz="-1.30757112180212E-11"
        izz="2.52619960333893E-07" />
    </inertial>
    <visual>
      <origin
        xyz="0 0 0"
        rpy="0 0 0" />
      <geometry>
        <mesh
          filename="package://robot_agv/meshes/link_camera.STL" />
      </geometry>
      <material
        name="">
        <color
          rgba="0.627450980392157 0.627450980392157 0.627450980392157 1" />
      </material>
    </visual>
    <collision>
      <origin
        xyz="0 0 0"
        rpy="0 0 0" />
      <geometry>
        <mesh
          filename="package://robot_agv/meshes/link_camera.STL" />
      </geometry>
    </collision>
  </link>
  <joint
    name="joint_camera"
    type="fixed">
    <origin
      xyz="0.0906778861058987 -0.0218736065266276 0.0267016521433842"
      rpy="0 0 1.5707963267949" />
    <parent
      link="base_link" />
    <child
      link="link_camera" />
    <axis
      xyz="0 0 0" />
  </joint>
</robot>